Workbook

Sheet Sources & Method
A1: Bandung SPMB Admission Predictor · worked example
A2: Data collected 23 October 2026 from official SPMB portals. No personal student data is stored; only per-school statistics (min, median, max, counts).
A4: Data | B4: Content | C4: Source
A5: Recap 2023–2025 | B5: Lowest and highest admitted score/distance per school per track (Recapitulation page). 2023–2024 = zoning, 2025 = domicile. | C5: https://spmb.bandung.go.id/recapitulation
A6: Quotas & applicants 2026 | B6: Final quota per track and applicant count per school (School Info page). | C6: https://spmb.bandung.go.id/school-info
A7: 2026 selection results, Round 1 | B7: Score and TKA of every student admitted via report-card and competition tracks, aggregated to min/median/max. | C7: https://spmb.bandung.go.id/selection-result/one-pharse
A8: 2026 selection results, Round 2 | B8: Distance of every student admitted via domicile, aggregated to the farthest distance (cut-off). | C8: https://spmb.bandung.go.id/selection-result/two-pharse
A9: Domicile zone | B9: The 19 public junior high schools in Zone B (east Bandung), from the Schools by Zone & Distance tool. | C9: https://spmb.bandung.go.id/home
A10: SPMB 2026 Guide | B10: Report-card score formula, rank bonus, competition score table, number of choices, round flow. | C10: https://spmb.bandung.go.id/document (PANDUAN SPMB 2026)
A11: SPMB West Java senior high 2026 | B11: Final standings per public senior high in Bandung: lowest/median report score, farthest domicile distance. Applicants' junior high is not published. | C11: https://spmb.jabarprov.go.id/sekolah
A12: Home location | B12: Example: Ujungberung town square. Change it in the yellow cells. | C12: Your input
A13: Example grades | B13: Made-up grades for two example students. Replace with real grades. | C13: Example
A15: Model assumptions (editable, yellow cells)
A16: Uncertainty of the student's TKA (points) | B16: 7 | C16: TKA not yet taken; ±7 points.
A17: Year-to-year cut-off volatility, selective schools | B17: 1.8 | C17: From 2023–2025 min-score variation (old scale), SMPN 8/17/56/50.
A18: Cut-off volatility, non-selective schools | B18: 3
A19: Risk an open school turns selective (outside Zone B) | B19: 0.3 | C19: Zone B uses each school's 2023–2025 history.
A20: Competition cut-off volatility | B20: 5
A21: Maximum competition-track probability | B21: 0.97 | C21: Residual certificate-verification risk.
A22: Minimum domicile cut-off uncertainty (log) | B22: 0.3
A23: Weight of 2023 in domicile cut-off | B23: 0.05
A24: Weight 2024 | B24: 0.15
A25: Weight 2025 | B25: 0.25
A26: Weight 2026 | B26: 0.55
A27: Senior high domicile cut-off uncertainty (log) | B27: 0.35
A28: Home latitude | B28: -6.9135 | C28: Example
A29: Home longitude | B29: 107.7005 | C29: Example
A31: How it is calculated
A32: • | B32: Report average = mean of 8 subjects (religion, Pancasila, Indonesian, mathematics, science & social, arts & crafts, physical ed., English) × 5 semesters (grades 4, 5, grade 6 sem 1). Sundanese and environmental studies are excluded.
A33: • | B33: Final TKA = mean of Indonesian and Mathematics TKA (admitted 2026 TKA scores always end in .00/.33/.67, consistent with averaging two scores).
A34: • | B34: Report score (2026 Guide): NA = 70% × (40% × report average + Bonus) + 30% × TKA; Bonus = 60 − (60/28) × (rank − 1) for ranks 1–3, otherwise 0.
A35: • | B35: Report-card probability, selective school (2026 min > 80): NORM.S.DIST((NA − min2026) / √((0.3·sdTKA)² + sdSel²)).
A36: • | B36: Report-card probability, open school: (1 − pflip) × NORM.S.DIST((NA − (min+1)) / √(..²+sdOpen²)) + pflip × NORM.S.DIST((NA − 85)/√(..²+2.5²)); pflip = min(0.6, selective years 2023–2025 ÷ 4 × 0.6).
A37: • | B37: Competition probability: MIN(capKej, NORM.S.DIST((highest certificate score − lowest admitted 2026 + 0.5) / sdKej)). Score 999 = direct admission (national champion).
A38: • | B38: Domicile probability: next year's distance cut-off is log-normal; μ = Σ weight × ln(that year's cut-off), σ = max(sdDomMin, weighted SD); probability = 1 − NORM.S.DIST((ln distance − μ)/σ).
A39: • | B39: Round 1 probability = 1 − (1−P1)(1−P2). Public school seat = 1 − (1−Round 1)(1−Round 2). Choices are treated as independent (a simplification).
A40: • | B40: Distance = straight line (haversine) from home coordinates to the school coordinates in the SPMB system.
A41: • | B41: Limitations: next year's rules are not published; no official teaching-quality data exists; cut-off scores and demand measure selectivity, not quality.

Sheet Calculator
A1: Calculator · edit the yellow cells (blue text = input)
A2: Empty semesters are skipped. Certificate codes: organizer gov / other / eduoffice / mass / none; level city / prov / nat / intl; type 0 = individual, 1 = team.
A4: Student A
A5: Subject | B5: G4 S1 | C5: G4 S2 | D5: G5 S1 | E5: G5 S2 | F5: G6 S1 | G5: Avg
A6: Religion (PABP) | B6: 88 | C6: 90 | D6: 91 | E6: 92 | G6: =IFERROR(AVERAGE(B6:F6),"") -> 90.25
A7: Pancasila | B7: 86 | C7: 88 | D7: 90 | E7: 91 | G7: =IFERROR(AVERAGE(B7:F7),"") -> 88.75
A8: Indonesian | B8: 87 | C8: 89 | D8: 88 | E8: 90 | G8: =IFERROR(AVERAGE(B8:F8),"") -> 88.5
A9: Mathematics | B9: 85 | C9: 88 | D9: 90 | E9: 92 | G9: =IFERROR(AVERAGE(B9:F9),"") -> 88.75
A10: Science & Social | B10: 86 | C10: 87 | D10: 90 | E10: 89 | G10: =IFERROR(AVERAGE(B10:F10),"") -> 88
A11: Arts & Crafts | B11: 88 | C11: 89 | D11: 90 | E11: 90 | G11: =IFERROR(AVERAGE(B11:F11),"") -> 89.25
A12: Physical Ed. | B12: 87 | C12: 88 | D12: 89 | E12: 90 | G12: =IFERROR(AVERAGE(B12:F12),"") -> 88.5
A13: English | B13: 89 | C13: 90 | D13: 91 | E13: 93 | G13: =IFERROR(AVERAGE(B13:F13),"") -> 90.75
A14: Semester avg | B14: =IFERROR(AVERAGE(B6:B13),"–") -> 87 | C14: =IFERROR(AVERAGE(C6:C13),"–") -> 88.625 | D14: =IFERROR(AVERAGE(D6:D13),"–") -> 89.875 | E14: =IFERROR(AVERAGE(E6:E13),"–") -> 90.875 | F14: =IFERROR(AVERAGE(F6:F13),"–") -> –
A16: Report average (8 subjects) | B16: =AVERAGE(B6:F13) -> 89.09375 | C16: Mean of all filled cells
A17: Class rank | B17: 2
A18: TKA Indonesian | B18: 82 | C18: Estimate
A19: TKA Mathematics | B19: 78 | C19: Estimate
A20: Final TKA | B20: =AVERAGE($B$18,$B$19) -> 80
A21: Rank bonus | B21: =IF($B$17<=3,60-(60/28)*($B$17-1),0) -> 57.857143
A22: Report score (NA) | B22: =0.7*(0.4*$B$16+$B$21)+0.3*$B$20 -> 89.44625 | C22: SPMB 2026 Guide
A23: Certificate 1: organizer / level / place / type | B23: none | C23: city | D23: 1 | E23: 1 | F23: =IF(B23="none",0,IFERROR(INDEX('Competition Scores'!$F:$F,MATCH(B23&"|"&C23&"|"&D23&"|"&E23,'Competition Scores'!$E:$E,0)),0)) -> 0 | G23: ← score
A24: Certificate 2: organizer / level / place / type | B24: none | C24: city | D24: 1 | E24: 1 | F24: =IF(B24="none",0,IFERROR(INDEX('Competition Scores'!$F:$F,MATCH(B24&"|"&C24&"|"&D24&"|"&E24,'Competition Scores'!$E:$E,0)),0)) -> 0 | G24: ← score
A25: Competition score (highest) | B25: =MAX(F23,F24) -> 0 | C25: 999 = direct admission
A26: Round 1 track | B26: report | C26: report / comp
A27: Choice 1 (code, e.g. N17) | B27: N17
A28: Choice 2 | B28: N46
A29: Choice 1 probability | B29: =IFERROR(IF($B$26="comp",INDEX('Schools 2026'!$S:$S,MATCH($B$27,'Schools 2026'!$A:$A,0)),INDEX('Schools 2026'!$Q:$Q,MATCH($B$27,'Schools 2026'!$A:$A,0))),0) -> 0.43911747
A30: Choice 2 probability | B30: =IF($B$28=$B$27,0,IFERROR(IF($B$26="comp",INDEX('Schools 2026'!$S:$S,MATCH($B$28,'Schools 2026'!$A:$A,0)),INDEX('Schools 2026'!$Q:$Q,MATCH($B$28,'Schools 2026'!$A:$A,0))),0)) -> 0.83971088
A31: Round 1 probability | B31: =1-(1-$B$29)*(1-$B$30) -> 0.91009663
A33: Student B
A34: Subject | B34: G4 S1 | C34: G4 S2 | D34: G5 S1 | E34: G5 S2 | F34: G6 S1 | G34: Avg
A35: Religion (PABP) | B35: 84 | C35: 86 | D35: 87 | E35: 88 | G35: =IFERROR(AVERAGE(B35:F35),"") -> 86.25
A36: Pancasila | B36: 83 | C36: 85 | D36: 86 | E36: 87 | G36: =IFERROR(AVERAGE(B36:F36),"") -> 85.25
A37: Indonesian | B37: 82 | C37: 84 | D37: 85 | E37: 86 | G37: =IFERROR(AVERAGE(B37:F37),"") -> 84.25
A38: Mathematics | B38: 80 | C38: 83 | D38: 84 | E38: 86 | G38: =IFERROR(AVERAGE(B38:F38),"") -> 83.25
A39: Science & Social | B39: 83 | C39: 84 | D39: 86 | E39: 85 | G39: =IFERROR(AVERAGE(B39:F39),"") -> 84.5
A40: Arts & Crafts | B40: 85 | C40: 86 | D40: 87 | E40: 87 | G40: =IFERROR(AVERAGE(B40:F40),"") -> 86.25
A41: Physical Ed. | B41: 90 | C41: 91 | D41: 92 | E41: 92 | G41: =IFERROR(AVERAGE(B41:F41),"") -> 91.25
A42: English | B42: 81 | C42: 83 | D42: 85 | E42: 86 | G42: =IFERROR(AVERAGE(B42:F42),"") -> 83.75
A43: Semester avg | B43: =IFERROR(AVERAGE(B35:B42),"–") -> 83.5 | C43: =IFERROR(AVERAGE(C35:C42),"–") -> 85.25 | D43: =IFERROR(AVERAGE(D35:D42),"–") -> 86.5 | E43: =IFERROR(AVERAGE(E35:E42),"–") -> 87.125 | F43: =IFERROR(AVERAGE(F35:F42),"–") -> –
...

Sheet Schools 2026
A1: Code | B1: School | C1: Zone | D1: Lat | E1: Lng | F1: Home distance (m) | G1: Report quota | H1: Report applicants | I1: Report demand (×) | J1: Report min score | K1: Report median score | L1: Admitted TKA median | M1: Competition quota | N1: Competition applicants | O1: Competition min score | P1: pflip (selective 2023–25) | Q1: Report prob. Student A | R1: Report prob. Student B | S1: Competition prob. Student A | T1: Competition prob. Student B | U1: Selectivity rank
A2: N1 | B2: SMPN 1 | C2: D | D2: -6.911579 | E2: 107.59658 | F2: =2*6371000*ASIN(SQRT(SIN(RADIANS(D2-'Sources & Method'!$B$28)/2)^2+COS(RADIANS('Sources & Method'!$B$28))*COS(RADIANS(D2))*SIN(RADIANS(E2-'Sources & Method'!$B$29)/2)^2)) -> 11473.59 | G2: 48 | H2: 96 | I2: =IF(G2=0,0,H2/G2) -> 2 | J2: 91.17 | K2: 92.401 | L2: 83.33 | M2: 32 | N2: 34 | O2: 20 | P2: ='Sources & Method'!$B$19 -> 0.3 | Q2: =IF(J2>80,NORMSDIST((Calculator!$B$22-J2)/SQRT((0.3*'Sources & Method'!$B$16)^2+'Sources & Method'!$B$17^2)),(1-P2)*NORMSDIST((Calculator!$B$22-(J2+1))/SQRT((0.3*'Sources & Method'!$B$16)^2+'Sources & Method'!$B$18^2))+P2*NORMSDIST((Calculator!$B$22-85)/SQRT((0.3*'Sources & Method'!$B$16)^2+2.5^2))) -> 0.26656895 | R2: =IF(J2>80,NORMSDIST((Calculator!$B$51-J2)/SQRT((0.3*'Sources & Method'!$B$16)^2+'Sources & Method'!$B$17^2)),(1-P2)*NORMSDIST((Calculator!$B$51-(J2+1))/SQRT((0.3*'Sources & Method'!$B$16)^2+'Sources & Method'!$B$18^2))+P2*NORMSDIST((Calculator!$B$51-85)/SQRT((0.3*'Sources & Method'!$B$16)^2+2.5^2))) -> 3.2570798e-60 | S2: =IF(OR(M2=0,O2="",Calculator!$B$25=0),0,IF(Calculator!$B$25>=999,'Sources & Method'!$B$21,MIN('Sources & Method'!$B$21,NORMSDIST((Calculator!$B$25-O2+0.5)/'Sources & Method'!$B$20)))) -> 0 | T2: =IF(OR(M2=0,O2="",Calculator!$B$54=0),0,IF(Calculator!$B$54>=999,'Sources & Method'!$B$21,MIN('Sources & Method'!$B$21,NORMSDIST((Calculator!$B$54-O2+0.5)/'Sources & Method'!$B$20)))) -> 0.97 | U2: =RANK(J2,$J$2:$J$76) -> 7
A3: N2 | B3: SMPN 2 | C3: A | D3: -6.913925 | E3: 107.61412 | F3: =2*6371000*ASIN(SQRT(SIN(RADIANS(D3-'Sources & Method'!$B$28)/2)^2+COS(RADIANS('Sources & Method'!$B$28))*COS(RADIANS(D3))*SIN(RADIANS(E3-'Sources & Method'!$B$29)/2)^2)) -> 9535.1822 | G3: 39 | H3: 74 | I3: =IF(G3=0,0,H3/G3) -> 1.8974359 | J3: 94.363 | K3: 95.189 | L3: 88.34 | M3: 26 | N3: 45 | O3: 32 | P3: ='Sources & Method'!$B$19 -> 0.3 | Q3: =IF(J3>80,NORMSDIST((Calculator!$B$22-J3)/SQRT((0.3*'Sources & Method'!$B$16)^2+'Sources & Method'!$B$17^2)),(1-P3)*NORMSDIST((Calculator!$B$22-(J3+1))/SQRT((0.3*'Sources & Method'!$B$16)^2+'Sources & Method'!$B$18^2))+P3*NORMSDIST((Calculator!$B$22-85)/SQRT((0.3*'Sources & Method'!$B$16)^2+2.5^2))) -> 0.037730291 | R3: =IF(J3>80,NORMSDIST((Calculator!$B$51-J3)/SQRT((0.3*'Sources & Method'!$B$16)^2+'Sources & Method'!$B$17^2)),(1-P3)*NORMSDIST((Calculator!$B$51-(J3+1))/SQRT((0.3*'Sources & Method'!$B$16)^2+'Sources & Method'!$B$18^2))+P3*NORMSDIST((Calculator!$B$51-85)/SQRT((0.3*'Sources & Method'!$B$16)^2+2.5^2))) -> 1.0209923e-68 | S3: =IF(OR(M3=0,O3="",Calculator!$B$25=0),0,IF(Calculator!$B$25>=999,'Sources & Method'!$B$21,MIN('Sources & Method'!$B$21,NORMSDIST((Calculator!$B$25-O3+0.5)/'Sources & Method'!$B$20)))) -> 0 | T3: =IF(OR(M3=0,O3="",Calculator!$B$54=0),0,IF(Calculator!$B$54>=999,'Sources & Method'!$B$21,MIN('Sources & Method'!$B$21,NORMSDIST((Calculator!$B$54-O3+0.5)/'Sources & Method'!$B$20)))) -> 0.97 | U3: =RANK(J3,$J$2:$J$76) -> 1
A4: N3 | B4: SMPN 3 | C4: C | D4: -6.929271 | E4: 107.60519 | F4: =2*6371000*ASIN(SQRT(SIN(RADIANS(D4-'Sources & Method'!$B$28)/2)^2+COS(RADIANS('Sources & Method'!$B$28))*COS(RADIANS(D4))*SIN(RADIANS(E4-'Sources & Method'!$B$29)/2)^2)) -> 10665.472 | G4: 39 | H4: 73 | I4: =IF(G4=0,0,H4/G4) -> 1.8717949 | J4: 89.485 | K4: 91.466 | L4: 80 | M4: 26 | N4: 35 | O4: 14 | P4: ='Sources & Method'!$B$19 -> 0.3 | Q4: =IF(J4>80,NORMSDIST((Calculator!$B$22-J4)/SQRT((0.3*'Sources & Method'!$B$16)^2+'Sources & Method'!$B$17^2)),(1-P4)*NORMSDIST((Calculator!$B$22-(J4+1))/SQRT((0.3*'Sources & Method'!$B$16)^2+'Sources & Method'!$B$18^2))+P4*NORMSDIST((Calculator!$B$22-85)/SQRT((0.3*'Sources & Method'!$B$16)^2+2.5^2))) -> 0.49441096 | R4: =IF(J4>80,NORMSDIST((Calculator!$B$51-J4)/SQRT((0.3*'Sources & Method'!$B$16)^2+'Sources & Method'!$B$17^2)),(1-P4)*NORMSDIST((Calculator!$B$51-(J4+1))/SQRT((0.3*'Sources & Method'!$B$16)^2+'Sources & Method'!$B$18^2))+P4*NORMSDIST((Calculator!$B$51-85)/SQRT((0.3*'Sources & Method'!$B$16)^2+2.5^2))) -> 5.8608253e-56 | S4: =IF(OR(M4=0,O4="",Calculator!$B$25=0),0,IF(Calculator!$B$25>=999,'Sources & Method'!$B$21,MIN('Sources & Method'!$B$21,NORMSDIST((Calculator!$B$25-O4+0.5)/'Sources & Method'!$B$20)))) -> 0 | T4: =IF(OR(M4=0,O4="",Calculator!$B$54=0),0,IF(Calculator!$B$54>=999,'Sources & Method'!$B$21,MIN('Sources & Method'!$B$21,NORMSDIST((Calculator!$B$54-O4+0.5)/'Sources & Method'!$B$20)))) -> 0.97 | U4: =RANK(J4,$J$2:$J$76) -> 12
A5: N4 | B5: SMPN 4 | C5: C | D5: -6.921139 | E5: 107.62598 | F5: =2*6371000*ASIN(SQRT(SIN(RADIANS(D5-'Sources & Method'!$B$28)/2)^2+COS(RADIANS('Sources & Method'!$B$28))*COS(RADIANS(D5))*SIN(RADIANS(E5-'Sources & Method'!$B$29)/2)^2)) -> 8270.109 | G5: 41 | H5: 65 | I5: =IF(G5=0,0,H5/G5) -> 1.5853659 | J5: 87.629 | K5: 89.74 | L5: 76.67 | M5: 28 | N5: 26 | O5: 5 | P5: ='Sources & Method'!$B$19 -> 0.3 | Q5: =IF(J5>80,NORMSDIST((Calculator!$B$22-J5)/SQRT((0.3*'Sources & Method'!$B$16)^2+'Sources & Method'!$B$17^2)),(1-P5)*NORMSDIST((Calculator!$B$22-(J5+1))/SQRT((0.3*'Sources & Method'!$B$16)^2+'Sources & Method'!$B$18^2))+P5*NORMSDIST((Calculator!$B$22-85)/SQRT((0.3*'Sources & Method'!$B$16)^2+2.5^2))) -> 0.74441858 | R5: =IF(J5>80,NORMSDIST((Calculator!$B$51-J5)/SQRT((0.3*'Sources & Method'!$B$16)^2+'Sources & Method'!$B$17^2)),(1-P5)*NORMSDIST((Calculator!$B$51-(J5+1))/SQRT((0.3*'Sources & Method'!$B$16)^2+'Sources & Method'!$B$18^2))+P5*NORMSDIST((Calculator!$B$51-85)/SQRT((0.3*'Sources & Method'!$B$16)^2+2.5^2))) -> 1.8582528e-51 | S5: =IF(OR(M5=0,O5="",Calculator!$B$25=0),0,IF(Calculator!$B$25>=999,'Sources & Method'!$B$21,MIN('Sources & Method'!$B$21,NORMSDIST((Calculator!$B$25-O5+0.5)/'Sources & Method'!$B$20)))) -> 0 | T5: =IF(OR(M5=0,O5="",Calculator!$B$54=0),0,IF(Calculator!$B$54>=999,'Sources & Method'!$B$21,MIN('Sources & Method'!$B$21,NORMSDIST((Calculator!$B$54-O5+0.5)/'Sources & Method'!$B$20)))) -> 0.97 | U5: =RANK(J5,$J$2:$J$76) -> 18
A6: N5 | B6: SMPN 5 | C6: A | D6: -6.914579 | E6: 107.61451 | F6: =2*6371000*ASIN(SQRT(SIN(RADIANS(D6-'Sources & Method'!$B$28)/2)^2+COS(RADIANS('Sources & Method'!$B$28))*COS(RADIANS(D6))*SIN(RADIANS(E6-'Sources & Method'!$B$29)/2)^2)) -> 9493.2076 | G6: 39 | H6: 87 | I6: =IF(G6=0,0,H6/G6) -> 2.2307692 | J6: 93.567 | K6: 94.751 | L6: 88.34 | M6: 26 | N6: 48 | O6: 32 | P6: ='Sources & Method'!$B$19 -> 0.3 | Q6: =IF(J6>80,NORMSDIST((Calculator!$B$22-J6)/SQRT((0.3*'Sources & Method'!$B$16)^2+'Sources & Method'!$B$17^2)),(1-P6)*NORMSDIST((Calculator!$B$22-(J6+1))/SQRT((0.3*'Sources & Method'!$B$16)^2+'Sources & Method'!$B$18^2))+P6*NORMSDIST((Calculator!$B$22-85)/SQRT((0.3*'Sources & Method'!$B$16)^2+2.5^2))) -> 0.068130485 | R6: =IF(J6>80,NORMSDIST((Calculator!$B$51-J6)/SQRT((0.3*'Sources & Method'!$B$16)^2+'Sources & Method'!$B$17^2)),(1-P6)*NORMSDIST((Calculator!$B$51-(J6+1))/SQRT((0.3*'Sources & Method'!$B$16)^2+'Sources & Method'!$B$18^2))+P6*NORMSDIST((Calculator!$B$51-85)/SQRT((0.3*'Sources & Method'!$B$16)^2+2.5^2))) -> 1.5239028e-66 | S6: =IF(OR(M6=0,O6="",Calculator!$B$25=0),0,IF(Calculator!$B$25>=999,'Sources & Method'!$B$21,MIN('Sources & Method'!$B$21,NORMSDIST((Calculator!$B$25-O6+0.5)/'Sources & Method'!$B$20)))) -> 0 | T6: =IF(OR(M6=0,O6="",Calculator!$B$54=0),0,IF(Calculator!$B$54>=999,'Sources & Method'!$B$21,MIN('Sources & Method'!$B$21,NORMSDIST((Calculator!$B$54-O6+0.5)/'Sources & Method'!$B$20)))) -> 0.97 | U6: =RANK(J6,$J$2:$J$76) -> 2
A7: N6 | B7: SMPN 6 | C7: D | D7: -6.91854 | E7: 107.60176 | F7: =2*6371000*ASIN(SQRT(SIN(RADIANS(D7-'Sources & Method'!$B$28)/2)^2+COS(RADIANS('Sources & Method'!$B$28))*COS(RADIANS(D7))*SIN(RADIANS(E7-'Sources & Method'!$B$29)/2)^2)) -> 10913.786 | G7: 62 | H7: 25 | I7: =IF(G7=0,0,H7/G7) -> 0.40322581 | J7: 44.756 | K7: 46.872 | L7: 71.66 | M7: 3 | N7: 1 | O7: 12 | P7: ='Sources & Method'!$B$19 -> 0.3 | Q7: =IF(J7>80,NORMSDIST((Calculator!$B$22-J7)/SQRT((0.3*'Sources & Method'!$B$16)^2+'Sources & Method'!$B$17^2)),(1-P7)*NORMSDIST((Calculator!$B$22-(J7+1))/SQRT((0.3*'Sources & Method'!$B$16)^2+'Sources & Method'!$B$18^2))+P7*NORMSDIST((Calculator!$B$22-85)/SQRT((0.3*'Sources & Method'!$B$16)^2+2.5^2))) -> 0.97401114 | R7: =IF(J7>80,NORMSDIST((Calculator!$B$51-J7)/SQRT((0.3*'Sources & Method'!$B$16)^2+'Sources & Method'!$B$17^2)),(1-P7)*NORMSDIST((Calculator!$B$51-(J7+1))/SQRT((0.3*'Sources & Method'!$B$16)^2+'Sources & Method'!$B$18^2))+P7*NORMSDIST((Calculator!$B$51-85)/SQRT((0.3*'Sources & Method'!$B$16)^2+2.5^2))) -> 0.36982983 | S7: =IF(OR(M7=0,O7="",Calculator!$B$25=0),0,IF(Calculator!$B$25>=999,'Sources & Method'!$B$21,MIN('Sources & Method'!$B$21,NORMSDIST((Calculator!$B$25-O7+0.5)/'Sources & Method'!$B$20)))) -> 0 | T7: =IF(OR(M7=0,O7="",Calculator!$B$54=0),0,IF(Calculator!$B$54>=999,'Sources & Method'!$B$21,MIN('Sources & Method'!$B$21,NORMSDIST((Calculator!$B$54-O7+0.5)/'Sources & Method'!$B$20)))) -> 0.97 | U7: =RANK(J7,$J$2:$J$76) -> 59
A8: N7 | B8: SMPN 7 | C8: A | D8: -6.90706 | E8: 107.61859 | F8: =2*6371000*ASIN(SQRT(SIN(RADIANS(D8-'Sources & Method'!$B$28)/2)^2+COS(RADIANS('Sources & Method'!$B$28))*COS(RADIANS(D8))*SIN(RADIANS(E8-'Sources & Method'!$B$29)/2)^2)) -> 9070.1264 | G8: 39 | H8: 63 | I8: =IF(G8=0,0,H8/G8) -> 1.6153846 | J8: 92.179 | K8: 93.385 | L8: 86.66 | M8: 26 | N8: 48 | O8: 26 | P8: ='Sources & Method'!$B$19 -> 0.3 | Q8: =IF(J8>80,NORMSDIST((Calculator!$B$22-J8)/SQRT((0.3*'Sources & Method'!$B$16)^2+'Sources & Method'!$B$17^2)),(1-P8)*NORMSDIST((Calculator!$B$22-(J8+1))/SQRT((0.3*'Sources & Method'!$B$16)^2+'Sources & Method'!$B$18^2))+P8*NORMSDIST((Calculator!$B$22-85)/SQRT((0.3*'Sources & Method'!$B$16)^2+2.5^2))) -> 0.16156951 | R8: =IF(J8>80,NORMSDIST((Calculator!$B$51-J8)/SQRT((0.3*'Sources & Method'!$B$16)^2+'Sources & Method'!$B$17^2)),(1-P8)*NORMSDIST((Calculator!$B$51-(J8+1))/SQRT((0.3*'Sources & Method'!$B$16)^2+'Sources & Method'!$B$18^2))+P8*NORMSDIST((Calculator!$B$51-85)/SQRT((0.3*'Sources & Method'!$B$16)^2+2.5^2))) -> 7.7255382e-63 | S8: =IF(OR(M8=0,O8="",Calculator!$B$25=0),0,IF(Calculator!$B$25>=999,'Sources & Method'!$B$21,MIN('Sources & Method'!$B$21,NORMSDIST((Calculator!$B$25-O8+0.5)/'Sources & Method'!$B$20)))) -> 0 | T8: =IF(OR(M8=0,O8="",Calculator!$B$54=0),0,IF(Calculator!$B$54>=999,'Sources & Method'!$B$21,MIN('Sources & Method'!$B$21,NORMSDIST((Calculator!$B$54-O8+0.5)/'Sources & Method'!$B$20)))) -> 0.97 | U8: =RANK(J8,$J$2:$J$76) -> 3
A9: N8 | B9: SMPN 8 | C9: B | D9: -6.91247 | E9: 107.70162 | F9: =2*6371000*ASIN(SQRT(SIN(RADIANS(D9-'Sources & Method'!$B$28)/2)^2+COS(RADIANS('Sources & Method'!$B$28))*COS(RADIANS(D9))*SIN(RADIANS(E9-'Sources & Method'!$B$29)/2)^2)) -> 168.12564 | G9: 20 | H9: 55 | I9: =IF(G9=0,0,H9/G9) -> 2.75 | J9: 92.179 | K9: 93.539 | L9: 85 | M9: 13 | N9: 20 | O9: 14 | P9: =MIN(0.6,COUNTIF(INDEX('Report 2023-2025'!$B$2:$D$20,MATCH(A9,'Report 2023-2025'!$A$2:$A$20,0),0),">80")/4*0.6) -> 0.45 | Q9: =IF(J9>80,NORMSDIST((Calculator!$B$22-J9)/SQRT((0.3*'Sources & Method'!$B$16)^2+'Sources & Method'!$B$17^2)),(1-P9)*NORMSDIST((Calculator!$B$22-(J9+1))/SQRT((0.3*'Sources & Method'!$B$16)^2+'Sources & Method'!$B$18^2))+P9*NORMSDIST((Calculator!$B$22-85)/SQRT((0.3*'Sources & Method'!$B$16)^2+2.5^2))) -> 0.16156951 | R9: =IF(J9>80,NORMSDIST((Calculator!$B$51-J9)/SQRT((0.3*'Sources & Method'!$B$16)^2+'Sources & Method'!$B$17^2)),(1-P9)*NORMSDIST((Calculator!$B$51-(J9+1))/SQRT((0.3*'Sources & Method'!$B$16)^2+'Sources & Method'!$B$18^2))+P9*NORMSDIST((Calculator!$B$51-85)/SQRT((0.3*'Sources & Method'!$B$16)^2+2.5^2))) -> 7.7255382e-63 | S9: =IF(OR(M9=0,O9="",Calculator!$B$25=0),0,IF(Calculator!$B$25>=999,'Sources & Method'!$B$21,MIN('Sources & Method'!$B$21,NORMSDIST((Calculator!$B$25-O9+0.5)/'Sources & Method'!$B$20)))) -> 0 | T9: =IF(OR(M9=0,O9="",Calculator!$B$54=0),0,IF(Calculator!$B$54>=999,'Sources & Method'!$B$21,MIN('Sources & Method'!$B$21,NORMSDIST((Calculator!$B$54-O9+0.5)/'Sources & Method'!$B$20)))) -> 0.97 | U9: =RANK(J9,$J$2:$J$76) -> 3
A10: N9 | B10: SMPN 9 | C10: D | D10: -6.908744 | E10: 107.59677 | F10: =2*6371000*ASIN(SQRT(SIN(RADIANS(D10-'Sources & Method'!$B$28)/2)^2+COS(RADIANS('Sources & Method'!$B$28))*COS(RADIANS(D10))*SIN(RADIANS(E10-'Sources & Method'!$B$29)/2)^2)) -> 11463.089 | G10: 48 | H10: 105 | I10: =IF(G10=0,0,H10/G10) -> 2.1875 | J10: 89.138 | K10: 90.707 | L10: 80 | M10: 32 | N10: 36 | O10: 14 | P10: ='Sources & Method'!$B$19 -> 0.3 | Q10: =IF(J10>80,NORMSDIST((Calculator!$B$22-J10)/SQRT((0.3*'Sources & Method'!$B$16)^2+'Sources & Method'!$B$17^2)),(1-P10)*NORMSDIST((Calculator!$B$22-(J10+1))/SQRT((0.3*'Sources & Method'!$B$16)^2+'Sources & Method'!$B$18^2))+P10*NORMSDIST((Calculator!$B$22-85)/SQRT((0.3*'Sources & Method'!$B$16)^2+2.5^2))) -> 0.54436946 | R10: =IF(J10>80,NORMSDIST((Calculator!$B$51-J10)/SQRT((0.3*'Sources & Method'!$B$16)^2+'Sources & Method'!$B$17^2)),(1-P10)*NORMSDIST((Calculator!$B$51-(J10+1))/SQRT((0.3*'Sources & Method'!$B$16)^2+'Sources & Method'!$B$18^2))+P10*NORMSDIST((Calculator!$B$51-85)/SQRT((0.3*'Sources & Method'!$B$16)^2+2.5^2))) -> 4.2101821e-55 | S10: =IF(OR(M10=0,O10="",Calculator!$B$25=0),0,IF(Calculator!$B$25>=999,'Sources & Method'!$B$21,MIN('Sources & Method'!$B$21,NORMSDIST((Calculator!$B$25-O10+0.5)/'Sources & Method'!$B$20)))) -> 0 | T10: =IF(OR(M10=0,O10="",Calculator!$B$54=0),0,IF(Calculator!$B$54>=999,'Sources & Method'!$B$21,MIN('Sources & Method'!$B$21,NORMSDIST((Calculator!$B$54-O10+0.5)/'Sources & Method'!$B$20)))) -> 0.97 | U10: =RANK(J10,$J$2:$J$76) -> 14
A11: N10 | B11: SMPN 10 | C11: C | D11: -6.929169 | E11: 107.60594 | F11: =2*6371000*ASIN(SQRT(SIN(RADIANS(D11-'Sources & Method'!$B$28)/2)^2+COS(RADIANS('Sources & Method'!$B$28))*COS(RADIANS(D11))*SIN(RADIANS(E11-'Sources & Method'!$B$29)/2)^2)) -> 10582.927 | G11: 29 | H11: 29 | I11: =IF(G11=0,0,H11/G11) -> 1 | J11: 86.425 | K11: 87.941 | L11: 73.33 | M11: 20 | N11: 9 | O11: 6 | P11: ='Sources & Method'!$B$19 -> 0.3 | Q11: =IF(J11>80,NORMSDIST((Calculator!$B$22-J11)/SQRT((0.3*'Sources & Method'!$B$16)^2+'Sources & Method'!$B$17^2)),(1-P11)*NORMSDIST((Calculator!$B$22-(J11+1))/SQRT((0.3*'Sources & Method'!$B$16)^2+'Sources & Method'!$B$18^2))+P11*NORMSDIST((Calculator!$B$22-85)/SQRT((0.3*'Sources & Method'!$B$16)^2+2.5^2))) -> 0.86265711 | R11: =IF(J11>80,NORMSDIST((Calculator!$B$51-J11)/SQRT((0.3*'Sources & Method'!$B$16)^2+'Sources & Method'!$B$17^2)),(1-P11)*NORMSDIST((Calculator!$B$51-(J11+1))/SQRT((0.3*'Sources & Method'!$B$16)^2+'Sources & Method'!$B$18^2))+P11*NORMSDIST((Calculator!$B$51-85)/SQRT((0.3*'Sources & Method'!$B$16)^2+2.5^2))) -> 1.2158978e-48 | S11: =IF(OR(M11=0,O11="",Calculator!$B$25=0),0,IF(Calculator!$B$25>=999,'Sources & Method'!$B$21,MIN('Sources & Method'!$B$21,NORMSDIST((Calculator!$B$25-O11+0.5)/'Sources & Method'!$B$20)))) -> 0 | T11: =IF(OR(M11=0,O11="",Calculator!$B$54=0),0,IF(Calculator!$B$54>=999,'Sources & Method'!$B$21,MIN('Sources & Method'!$B$21,NORMSDIST((Calculator!$B$54-O11+0.5)/'Sources & Method'!$B$20)))) -> 0.97 | U11: =RANK(J11,$J$2:$J$76) -> 24
A12: N11 | B12: SMPN 11 | C12: C | D12: -6.934838 | E12: 107.60801 | F12: =2*6371000*ASIN(SQRT(SIN(RADIANS(D12-'Sources & Method'!$B$28)/2)^2+COS(RADIANS('Sources & Method'!$B$28))*COS(RADIANS(D12))*SIN(RADIANS(E12-'Sources & Method'!$B$29)/2)^2)) -> 10481.276 | G12: 44 | H12: 57 | I12: =IF(G12=0,0,H12/G12) -> 1.2954545 | J12: 88.242 | K12: 91.402 | L12: 80 | M12: 29 | N12: 38 | O12: 12 | P12: ='Sources & Method'!$B$19 -> 0.3 | Q12: =IF(J12>80,NORMSDIST((Calculator!$B$22-J12)/SQRT((0.3*'Sources & Method'!$B$16)^2+'Sources & Method'!$B$17^2)),(1-P12)*NORMSDIST((Calculator!$B$22-(J12+1))/SQRT((0.3*'Sources & Method'!$B$16)^2+'Sources & Method'!$B$18^2))+P12*NORMSDIST((Calculator!$B$22-85)/SQRT((0.3*'Sources & Method'!$B$16)^2+2.5^2))) -> 0.66836304 | R12: =IF(J12>80,NORMSDIST((Calculator!$B$51-J12)/SQRT((0.3*'Sources & Method'!$B$16)^2+'Sources & Method'!$B$17^2)),(1-P12)*NORMSDIST((Calculator!$B$51-(J12+1))/SQRT((0.3*'Sources & Method'!$B$16)^2+'Sources & Method'!$B$18^2))+P12*NORMSDIST((Calculator!$B$51-85)/SQRT((0.3*'Sources & Method'!$B$16)^2+2.5^2))) -> 6.3680178e-53 | S12: =IF(OR(M12=0,O12="",Calculator!$B$25=0),0,IF(Calculator!$B$25>=999,'Sources & Method'!$B$21,MIN('Sources & Method'!$B$21,NORMSDIST((Calculator!$B$25-O12+0.5)/'Sources & Method'!$B$20)))) -> 0 | T12: =IF(OR(M12=0,O12="",Calculator!$B$54=0),0,IF(Calculator!$B$54>=999,'Sources & Method'!$B$21,MIN('Sources & Method'!$B$21,NORMSDIST((Calculator!$B$54-O12+0.5)/'Sources & Method'!$B$20)))) -> 0.97 | U12: =RANK(J12,$J$2:$J$76) -> 16
A13: N12 | B13: SMPN 12 | C13: A | D13: -6.865987 | E13: 107.59362 | F13: =2*6371000*ASIN(SQRT(SIN(RADIANS(D13-'Sources & Method'!$B$28)/2)^2+COS(RADIANS('Sources & Method'!$B$28))*COS(RADIANS(D13))*SIN(RADIANS(E13-'Sources & Method'!$B$29)/2)^2)) -> 12927.847 | G13: 34 | H13: 78 | I13: =IF(G13=0,0,H13/G13) -> 2.2941176 | J13: 90.848 | K13: 92.818 | L13: 85 | M13: 23 | N13: 35 | O13: 20 | P13: ='Sources & Method'!$B$19 -> 0.3 | Q13: =IF(J13>80,NORMSDIST((Calculator!$B$22-J13)/SQRT((0.3*'Sources & Method'!$B$16)^2+'Sources & Method'!$B$17^2)),(1-P13)*NORMSDIST((Calculator!$B$22-(J13+1))/SQRT((0.3*'Sources & Method'!$B$16)^2+'Sources & Method'!$B$18^2))+P13*NORMSDIST((Calculator!$B$22-85)/SQRT((0.3*'Sources & Method'!$B$16)^2+2.5^2))) -> 0.30614625 | R13: =IF(J13>80,NORMSDIST((Calculator!$B$51-J13)/SQRT((0.3*'Sources & Method'!$B$16)^2+'Sources & Method'!$B$17^2)),(1-P13)*NORMSDIST((Calculator!$B$51-(J13+1))/SQRT((0.3*'Sources & Method'!$B$16)^2+'Sources & Method'!$B$18^2))+P13*NORMSDIST((Calculator!$B$51-85)/SQRT((0.3*'Sources & Method'!$B$16)^2+2.5^2))) -> 2.1796451e-59 | S13: =IF(OR(M13=0,O13="",Calculator!$B$25=0),0,IF(Calculator!$B$25>=999,'Sources & Method'!$B$21,MIN('Sources & Method'!$B$21,NORMSDIST((Calculator!$B$25-O13+0.5)/'Sources & Method'!$B$20)))) -> 0 | T13: =IF(OR(M13=0,O13="",Calculator!$B$54=0),0,IF(Calculator!$B$54>=999,'Sources & Method'!$B$21,MIN('Sources & Method'!$B$21,NORMSDIST((Calculator!$B$54-O13+0.5)/'Sources & Method'!$B$20)))) -> 0.97 | U13: =RANK(J13,$J$2:$J$76) -> 8
A14: N13 | B14: SMPN 13 | C14: C | D14: -6.935746 | E14: 107.62268 | F14: =2*6371000*ASIN(SQRT(SIN(RADIANS(D14-'Sources & Method'!$B$28)/2)^2+COS(RADIANS('Sources & Method'!$B$28))*COS(RADIANS(D14))*SIN(RADIANS(E14-'Sources & Method'!$B$29)/2)^2)) -> 8939.563 | G14: 44 | H14: 71 | I14: =IF(G14=0,0,H14/G14) -> 1.6136364 | J14: 92 | K14: 93.399 | L14: 85 | M14: 29 | N14: 36 | O14: 24 | P14: ='Sources & Method'!$B$19 -> 0.3 | Q14: =IF(J14>80,NORMSDIST((Calculator!$B$22-J14)/SQRT((0.3*'Sources & Method'!$B$16)^2+'Sources & Method'!$B$17^2)),(1-P14)*NORMSDIST((Calculator!$B$22-(J14+1))/SQRT((0.3*'Sources & Method'!$B$16)^2+'Sources & Method'!$B$18^2))+P14*NORMSDIST((Calculator!$B$22-85)/SQRT((0.3*'Sources & Method'!$B$16)^2+2.5^2))) -> 0.17792277 | R14: =IF(J14>80,NORMSDIST((Calculator!$B$51-J14)/SQRT((0.3*'Sources & Method'!$B$16)^2+'Sources & Method'!$B$17^2)),(1-P14)*NORMSDIST((Calculator!$B$51-(J14+1))/SQRT((0.3*'Sources & Method'!$B$16)^2+'Sources & Method'!$B$18^2))+P14*NORMSDIST((Calculator!$B$51-85)/SQRT((0.3*'Sources & Method'!$B$16)^2+2.5^2))) -> 2.279276e-62 | S14: =IF(OR(M14=0,O14="",Calculator!$B$25=0),0,IF(Calculator!$B$25>=999,'Sources & Method'!$B$21,MIN('Sources & Method'!$B$21,NORMSDIST((Calculator!$B$25-O14+0.5)/'Sources & Method'!$B$20)))) -> 0 | T14: =IF(OR(M14=0,O14="",Calculator!$B$54=0),0,IF(Calculator!$B$54>=999,'Sources & Method'!$B$21,MIN('Sources & Method'!$B$21,NORMSDIST((Calculator!$B$54-O14+0.5)/'Sources & Method'!$B$20)))) -> 0.97 | U14: =RANK(J14,$J$2:$J$76) -> 5
A15: N14 | B15: SMPN 14 | C15: A | D15: -6.9081 | E15: 107.6304 | F15: =2*6371000*ASIN(SQRT(SIN(RADIANS(D15-'Sources & Method'!$B$28)/2)^2+COS(RADIANS('Sources & Method'!$B$28))*COS(RADIANS(D15))*SIN(RADIANS(E15-'Sources & Method'!$B$29)/2)^2)) -> 7761.3945 | G15: 39 | H15: 96 | I15: =IF(G15=0,0,H15/G15) -> 2.4615385 | J15: 91.99 | K15: 93.428 | L15: 85 | M15: 26 | N15: 37 | O15: 22 | P15: ='Sources & Method'!$B$19 -> 0.3 | Q15: =IF(J15>80,NORMSDIST((Calculator!$B$22-J15)/SQRT((0.3*'Sources & Method'!$B$16)^2+'Sources & Method'!$B$17^2)),(1-P15)*NORMSDIST((Calculator!$B$22-(J15+1))/SQRT((0.3*'Sources & Method'!$B$16)^2+'Sources & Method'!$B$18^2))+P15*NORMSDIST((Calculator!$B$22-85)/SQRT((0.3*'Sources & Method'!$B$16)^2+2.5^2))) -> 0.17886615 | R15: =IF(J15>80,NORMSDIST((Calculator!$B$51-J15)/SQRT((0.3*'Sources & Method'!$B$16)^2+'Sources & Method'!$B$17^2)),(1-P15)*NORMSDIST((Calculator!$B$51-(J15+1))/SQRT((0.3*'Sources & Method'!$B$16)^2+'Sources & Method'!$B$18^2))+P15*NORMSDIST((Calculator!$B$51-85)/SQRT((0.3*'Sources & Method'!$B$16)^2+2.5^2))) -> 2.4209904e-62 | S15: =IF(OR(M15=0,O15="",Calculator!$B$25=0),0,IF(Calculator!$B$25>=999,'Sources & Method'!$B$21,MIN('Sources & Method'!$B$21,NORMSDIST((Calculator!$B$25-O15+0.5)/'Sources & Method'!$B$20)))) -> 0 | T15: =IF(OR(M15=0,O15="",Calculator!$B$54=0),0,IF(Calculator!$B$54>=999,'Sources & Method'!$B$21,MIN('Sources & Method'!$B$21,NORMSDIST((Calculator!$B$54-O15+0.5)/'Sources & Method'!$B$20)))) -> 0.97 | U15: =RANK(J15,$J$2:$J$76) -> 6
A16: N15 | B16: SMPN 15 | C16: A | D16: -6.87443 | E16: 107.59568 | F16: =2*6371000*ASIN(SQRT(SIN(RADIANS(D16-'Sources & Method'!$B$28)/2)^2+COS(RADIANS('Sources & Method'!$B$28))*COS(RADIANS(D16))*SIN(RADIANS(E16-'Sources & Method'!$B$29)/2)^2)) -> 12359.853 | G16: 24 | H16: 41 | I16: =IF(G16=0,0,H16/G16) -> 1.7083333 | J16: 87.513 | K16: 89.244 | L16: 76.67 | M16: 16 | N16: 15 | O16: 12 | P16: ='Sources & Method'!$B$19 -> 0.3 | Q16: =IF(J16>80,NORMSDIST((Calculator!$B$22-J16)/SQRT((0.3*'Sources & Method'!$B$16)^2+'Sources & Method'!$B$17^2)),(1-P16)*NORMSDIST((Calculator!$B$22-(J16+1))/SQRT((0.3*'Sources & Method'!$B$16)^2+'Sources & Method'!$B$18^2))+P16*NORMSDIST((Calculator!$B$22-85)/SQRT((0.3*'Sources & Method'!$B$16)^2+2.5^2))) -> 0.75771399 | R16: =IF(J16>80,NORMSDIST((Calculator!$B$51-J16)/SQRT((0.3*'Sources & Method'!$B$16)^2+'Sources & Method'!$B$17^2)),(1-P16)*NORMSDIST((Calculator!$B$51-(J16+1))/SQRT((0.3*'Sources & Method'!$B$16)^2+'Sources & Method'!$B$18^2))+P16*NORMSDIST((Calculator!$B$51-85)/SQRT((0.3*'Sources & Method'!$B$16)^2+2.5^2))) -> 3.4991329e-51 | S16: =IF(OR(M16=0,O16="",Calculator!$B$25=0),0,IF(Calculator!$B$25>=999,'Sources & Method'!$B$21,MIN('Sources & Method'!$B$21,NORMSDIST((Calculator!$B$25-O16+0.5)/'Sources & Method'!$B$20)))) -> 0 | T16: =IF(OR(M16=0,O16="",Calculator!$B$54=0),0,IF(Calculator!$B$54>=999,'Sources & Method'!$B$21,MIN('Sources & Method'!$B$21,NORMSDIST((Calculator!$B$54-O16+0.5)/'Sources & Method'!$B$20)))) -> 0.97 | U16: =RANK(J16,$J$2:$J$76) -> 19
A17: N16 | B17: SMPN 16 | C17: A | D17: -6.899355 | E17: 107.6425 | F17: =2*6371000*ASIN(SQRT(SIN(RADIANS(D17-'Sources & Method'!$B$28)/2)^2+COS(RADIANS('Sources & Method'!$B$28))*COS(RADIANS(D17))*SIN(RADIANS(E17-'Sources & Method'!$B$29)/2)^2)) -> 6592.4447 | G17: 34 | H17: 42 | I17: =IF(G17=0,0,H17/G17) -> 1.2352941 | J17: 86.717 | K17: 88.718 | L17: 75 | M17: 23 | N17: 30 | O17: 14 | P17: ='Sources & Method'!$B$19 -> 0.3 | Q17: =IF(J17>80,NORMSDIST((Calculator!$B$22-J17)/SQRT((0.3*'Sources & Method'!$B$16)^2+'Sources & Method'!$B$17^2)),(1-P17)*NORMSDIST((Calculator!$B$22-(J17+1))/SQRT((0.3*'Sources & Method'!$B$16)^2+'Sources & Method'!$B$18^2))+P17*NORMSDIST((Calculator!$B$22-85)/SQRT((0.3*'Sources & Method'!$B$16)^2+2.5^2))) -> 0.83812044 | R17: =IF(J17>80,NORMSDIST((Calculator!$B$51-J17)/SQRT((0.3*'Sources & Method'!$B$16)^2+'Sources & Method'!$B$17^2)),(1-P17)*NORMSDIST((Calculator!$B$51-(J17+1))/SQRT((0.3*'Sources & Method'!$B$16)^2+'Sources & Method'!$B$18^2))+P17*NORMSDIST((Calculator!$B$51-85)/SQRT((0.3*'Sources & Method'!$B$16)^2+2.5^2))) -> 2.5675726e-49 | S17: =IF(OR(M17=0,O17="",Calculator!$B$25=0),0,IF(Calculator!$B$25>=999,'Sources & Method'!$B$21,MIN('Sources & Method'!$B$21,NORMSDIST((Calculator!$B$25-O17+0.5)/'Sources & Method'!$B$20)))) -> 0 | T17: =IF(OR(M17=0,O17="",Calculator!$B$54=0),0,IF(Calculator!$B$54>=999,'Sources & Method'!$B$21,MIN('Sources & Method'!$B$21,NORMSDIST((Calculator!$B$54-O17+0.5)/'Sources & Method'!$B$20)))) -> 0.97 | U17: =RANK(J17,$J$2:$J$76) -> 21
A18: N17 | B18: SMPN 17 | C18: B | D18: -6.906659 | E18: 107.67271 | F18: =2*6371000*ASIN(SQRT(SIN(RADIANS(D18-'Sources & Method'!$B$28)/2)^2+COS(RADIANS('Sources & Method'!$B$28))*COS(RADIANS(D18))*SIN(RADIANS(E18-'Sources & Method'!$B$29)/2)^2)) -> 3160.7815 | G18: 44 | H18: 101 | I18: =IF(G18=0,0,H18/G18) -> 2.2954545 | J18: 89.87 | K18: 91.269 | L18: 81.66 | M18: 29 | N18: 46 | O18: 14 | P18: =MIN(0.6,COUNTIF(INDEX('Report 2023-2025'!$B$2:$D$20,MATCH(A18,'Report 2023-2025'!$A$2:$A$20,0),0),">80")/4*0.6) -> 0.45 | Q18: =IF(J18>80,NORMSDIST((Calculator!$B$22-J18)/SQRT((0.3*'Sources & Method'!$B$16)^2+'Sources & Method'!$B$17^2)),(1-P18)*NORMSDIST((Calculator!$B$22-(J18+1))/SQRT((0.3*'Sources & Method'!$B$16)^2+'Sources & Method'!$B$18^2))+P18*NORMSDIST((Calculator!$B$22-85)/SQRT((0.3*'Sources & Method'!$B$16)^2+2.5^2))) -> 0.43911747 | R18: =IF(J18>80,NORMSDIST((Calculator!$B$51-J18)/SQRT((0.3*'Sources & Method'!$B$16)^2+'Sources & Method'!$B$17^2)),(1-P18)*NORMSDIST((Calculator!$B$51-(J18+1))/SQRT((0.3*'Sources & Method'!$B$16)^2+'Sources & Method'!$B$18^2))+P18*NORMSDIST((Calculator!$B$51-85)/SQRT((0.3*'Sources & Method'!$B$16)^2+2.5^2))) -> 6.4546196e-57 | S18: =IF(OR(M18=0,O18="",Calculator!$B$25=0),0,IF(Calculator!$B$25>=999,'Sources & Method'!$B$21,MIN('Sources & Method'!$B$21,NORMSDIST((Calculator!$B$25-O18+0.5)/'Sources & Method'!$B$20)))) -> 0 | T18: =IF(OR(M18=0,O18="",Calculator!$B$54=0),0,IF(Calculator!$B$54>=999,'Sources & Method'!$B$21,MIN('Sources & Method'!$B$21,NORMSDIST((Calculator!$B$54-O18+0.5)/'Sources & Method'!$B$20)))) -> 0.97 | U18: =RANK(J18,$J$2:$J$76) -> 9
A19: N18 | B19: SMPN 18 | C19: B | D19: -6.951869 | E19: 107.64169 | F19: =2*6371000*ASIN(SQRT(SIN(RADIANS(D19-'Sources & Method'!$B$28)/2)^2+COS(RADIANS('Sources & Method'!$B$28))*COS(RADIANS(D19))*SIN(RADIANS(E19-'Sources & Method'!$B$29)/2)^2)) -> 7767.9751 | G19: 48 | H19: 49 | I19: =IF(G19=0,0,H19/G19) -> 1.0208333 | J19: 85.59 | K19: 87.926 | L19: 73.34 | M19: 32 | N19: 22 | O19: 10 | P19: =MIN(0.6,COUNTIF(INDEX('Report 2023-2025'!$B$2:$D$20,MATCH(A19,'Report 2023-2025'!$A$2:$A$20,0),0),">80")/4*0.6) -> 0.45 | Q19: =IF(J19>80,NORMSDIST((Calculator!$B$22-J19)/SQRT((0.3*'Sources & Method'!$B$16)^2+'Sources & Method'!$B$17^2)),(1-P19)*NORMSDIST((Calculator!$B$22-(J19+1))/SQRT((0.3*'Sources & Method'!$B$16)^2+'Sources & Method'!$B$18^2))+P19*NORMSDIST((Calculator!$B$22-85)/SQRT((0.3*'Sources & Method'!$B$16)^2+2.5^2))) -> 0.91837594 | R19: =IF(J19>80,NORMSDIST((Calculator!$B$51-J19)/SQRT((0.3*'Sources & Method'!$B$16)^2+'Sources & Method'!$B$17^2)),(1-P19)*NORMSDIST((Calculator!$B$51-(J19+1))/SQRT((0.3*'Sources & Method'!$B$16)^2+'Sources & Method'!$B$18^2))+P19*NORMSDIST((Calculator!$B$51-85)/SQRT((0.3*'Sources & Method'!$B$16)^2+2.5^2))) -> 9.7634007e-47 | S19: =IF(OR(M19=0,O19="",Calculator!$B$25=0),0,IF(Calculator!$B$25>=999,'Sources & Method'!$B$21,MIN('Sources & Method'!$B$21,NORMSDIST((Calculator!$B$25-O19+0.5)/'Sources & Method'!$B$20)))) -> 0 | T19: =IF(OR(M19=0,O19="",Calculator!$B$54=0),0,IF(Calculator!$B$54>=999,'Sources & Method'!$B$21,MIN('Sources & Method'!$B$21,NORMSDIST((Calculator!$B$54-O19+0.5)/'Sources & Method'!$B$20)))) -> 0.97 | U19: =RANK(J19,$J$2:$J$76) -> 27
A20: N19 | B20: SMPN 19 | C20: A | D20: -6.886426 | E20: 107.62206 | F20: =2*6371000*ASIN(SQRT(SIN(RADIANS(D20-'Sources & Method'!$B$28)/2)^2+COS(RADIANS('Sources & Method'!$B$28))*COS(RADIANS(D20))*SIN(RADIANS(E20-'Sources & Method'!$B$29)/2)^2)) -> 9167.0551 | G20: 39 | H20: 39 | I20: =IF(G20=0,0,H20/G20) -> 1 | J20: 81.761 | K20: 86.094 | L20: 68.34 | M20: 26 | N20: 23 | O20: 8 | P20: ='Sources & Method'!$B$19 -> 0.3 | Q20: =IF(J20>80,NORMSDIST((Calculator!$B$22-J20)/SQRT((0.3*'Sources & Method'!$B$16)^2+'Sources & Method'!$B$17^2)),(1-P20)*NORMSDIST((Calculator!$B$22-(J20+1))/SQRT((0.3*'Sources & Method'!$B$16)^2+'Sources & Method'!$B$18^2))+P20*NORMSDIST((Calculator!$B$22-85)/SQRT((0.3*'Sources & Method'!$B$16)^2+2.5^2))) -> 0.99727038 | R20: =IF(J20>80,NORMSDIST((Calculator!$B$51-J20)/SQRT((0.3*'Sources & Method'!$B$16)^2+'Sources & Method'!$B$17^2)),(1-P20)*NORMSDIST((Calculator!$B$51-(J20+1))/SQRT((0.3*'Sources & Method'!$B$16)^2+'Sources & Method'!$B$18^2))+P20*NORMSDIST((Calculator!$B$51-85)/SQRT((0.3*'Sources & Method'!$B$16)^2+2.5^2))) -> 1.6576151e-38 | S20: =IF(OR(M20=0,O20="",Calculator!$B$25=0),0,IF(Calculator!$B$25>=999,'Sources & Method'!$B$21,MIN('Sources & Method'!$B$21,NORMSDIST((Calculator!$B$25-O20+0.5)/'Sources & Method'!$B$20)))) -> 0 | T20: =IF(OR(M20=0,O20="",Calculator!$B$54=0),0,IF(Calculator!$B$54>=999,'Sources & Method'!$B$21,MIN('Sources & Method'!$B$21,NORMSDIST((Calculator!$B$54-O20+0.5)/'Sources & Method'!$B$20)))) -> 0.97 | U20: =RANK(J20,$J$2:$J$76) -> 33
A21: N20 | B21: SMPN 20 | C21: C | D21: -6.9195 | E21: 107.6261 | F21: =2*6371000*ASIN(SQRT(SIN(RADIANS(D21-'Sources & Method'!$B$28)/2)^2+COS(RADIANS('Sources & Method'!$B$28))*COS(RADIANS(D21))*SIN(RADIANS(E21-'Sources & Method'!$B$29)/2)^2)) -> 8239.7528 | G21: 57 | H21: 17 | I21: =IF(G21=0,0,H21/G21) -> 0.29824561 | J21: 48.201 | K21: 73.845 | L21: 75 | M21: 8 | N21: 6 | O21: 4 | P21: ='Sources & Method'!$B$19 -> 0.3 | Q21: =IF(J21>80,NORMSDIST((Calculator!$B$22-J21)/SQRT((0.3*'Sources & Method'!$B$16)^2+'Sources & Method'!$B$17^2)),(1-P21)*NORMSDIST((Calculator!$B$22-(J21+1))/SQRT((0.3*'Sources & Method'!$B$16)^2+'Sources & Method'!$B$18^2))+P21*NORMSDIST((Calculator!$B$22-85)/SQRT((0.3*'Sources & Method'!$B$16)^2+2.5^2))) -> 0.97401114 | R21: =IF(J21>80,NORMSDIST((Calculator!$B$51-J21)/SQRT((0.3*'Sources & Method'!$B$16)^2+'Sources & Method'!$B$17^2)),(1-P21)*NORMSDIST((Calculator!$B$51-(J21+1))/SQRT((0.3*'Sources & Method'!$B$16)^2+'Sources & Method'!$B$18^2))+P21*NORMSDIST((Calculator!$B$51-85)/SQRT((0.3*'Sources & Method'!$B$16)^2+2.5^2))) -> 0.13456579 | S21: =IF(OR(M21=0,O21="",Calculator!$B$25=0),0,IF(Calculator!$B$25>=999,'Sources & Method'!$B$21,MIN('Sources & Method'!$B$21,NORMSDIST((Calculator!$B$25-O21+0.5)/'Sources & Method'!$B$20)))) -> 0 | T21: =IF(OR(M21=0,O21="",Calculator!$B$54=0),0,IF(Calculator!$B$54>=999,'Sources & Method'!$B$21,MIN('Sources & Method'!$B$21,NORMSDIST((Calculator!$B$54-O21+0.5)/'Sources & Method'!$B$20)))) -> 0.97 | U21: =RANK(J21,$J$2:$J$76) -> 40
A22: N21 | B22: SMPN 21 | C22: D | D22: -6.945635 | E22: 107.58019 | F22: =2*6371000*ASIN(SQRT(SIN(RADIANS(D22-'Sources & Method'!$B$28)/2)^2+COS(RADIANS('Sources & Method'!$B$28))*COS(RADIANS(D22))*SIN(RADIANS(E22-'Sources & Method'!$B$29)/2)^2)) -> 13752.888 | G22: 49 | H22: 41 | I22: =IF(G22=0,0,H22/G22) -> 0.83673469 | J22: 47.315 | K22: 80.758 | L22: 75 | M22: 4 | N22: 3 | O22: 8 | P22: ='Sources & Method'!$B$19 -> 0.3 | Q22: =IF(J22>80,NORMSDIST((Calculator!$B$22-J22)/SQRT((0.3*'Sources & Method'!$B$16)^2+'Sources & Method'!$B$17^2)),(1-P22)*NORMSDIST((Calculator!$B$22-(J22+1))/SQRT((0.3*'Sources & Method'!$B$16)^2+'Sources & Method'!$B$18^2))+P22*NORMSDIST((Calculator!$B$22-85)/SQRT((0.3*'Sources & Method'!$B$16)^2+2.5^2))) -> 0.97401114 | R22: =IF(J22>80,NORMSDIST((Calculator!$B$51-J22)/SQRT((0.3*'Sources & Method'!$B$16)^2+'Sources & Method'!$B$17^2)),(1-P22)*NORMSDIST((Calculator!$B$51-(J22+1))/SQRT((0.3*'Sources & Method'!$B$16)^2+'Sources & Method'!$B$18^2))+P22*NORMSDIST((Calculator!$B$51-85)/SQRT((0.3*'Sources & Method'!$B$16)^2+2.5^2))) -> 0.18556181 | S22: =IF(OR(M22=0,O22="",Calculator!$B$25=0),0,IF(Calculator!$B$25>=999,'Sources & Method'!$B$21,MIN('Sources & Method'!$B$21,NORMSDIST((Calculator!$B$25-O22+0.5)/'Sources & Method'!$B$20)))) -> 0 | T22: =IF(OR(M22=0,O22="",Calculator!$B$54=0),0,IF(Calculator!$B$54>=999,'Sources & Method'!$B$21,MIN('Sources & Method'!$B$21,NORMSDIST((Calculator!$B$54-O22+0.5)/'Sources & Method'!$B$20)))) -> 0.97 | U22: =RANK(J22,$J$2:$J$76) -> 43
A23: N22 | B23: SMPN 22 | C23: A | D23: -6.911952 | E23: 107.63386 | F23: =2*6371000*ASIN(SQRT(SIN(RADIANS(D23-'Sources & Method'!$B$28)/2)^2+COS(RADIANS('Sources & Method'!$B$28))*COS(RADIANS(D23))*SIN(RADIANS(E23-'Sources & Method'!$B$29)/2)^2)) -> 7358.398 | G23: 34 | H23: 43 | I23: =IF(G23=0,0,H23/G23) -> 1.2647059 | J23: 87.666 | K23: 89.265 | L23: 75 | M23: 23 | N23: 20 | O23: 12 | P23: ='Sources & Method'!$B$19 -> 0.3 | Q23: =IF(J23>80,NORMSDIST((Calculator!$B$22-J23)/SQRT((0.3*'Sources & Method'!$B$16)^2+'Sources & Method'!$B$17^2)),(1-P23)*NORMSDIST((Calculator!$B$22-(J23+1))/SQRT((0.3*'Sources & Method'!$B$16)^2+'Sources & Method'!$B$18^2))+P23*NORMSDIST((Calculator!$B$22-85)/SQRT((0.3*'Sources & Method'!$B$16)^2+2.5^2))) -> 0.74009903 | R23: =IF(J23>80,NORMSDIST((Calculator!$B$51-J23)/SQRT((0.3*'Sources & Method'!$B$16)^2+'Sources & Method'!$B$17^2)),(1-P23)*NORMSDIST((Calculator!$B$51-(J23+1))/SQRT((0.3*'Sources & Method'!$B$16)^2+'Sources & Method'!$B$18^2))+P23*NORMSDIST((Calculator!$B$51-85)/SQRT((0.3*'Sources & Method'!$B$16)^2+2.5^2))) -> 1.5180124e-51 | S23: =IF(OR(M23=0,O23="",Calculator!$B$25=0),0,IF(Calculator!$B$25>=999,'Sources & Method'!$B$21,MIN('Sources & Method'!$B$21,NORMSDIST((Calculator!$B$25-O23+0.5)/'Sources & Method'!$B$20)))) -> 0 | T23: =IF(OR(M23=0,O23="",Calculator!$B$54=0),0,IF(Calculator!$B$54>=999,'Sources & Method'!$B$21,MIN('Sources & Method'!$B$21,NORMSDIST((Calculator!$B$54-O23+0.5)/'Sources & Method'!$B$20)))) -> 0.97 | U23: =RANK(J23,$J$2:$J$76) -> 17
A24: N23 | B24: SMPN 23 | C24: D | D24: -6.914834 | E24: 107.5896 | F24: =2*6371000*ASIN(SQRT(SIN(RADIANS(D24-'Sources & Method'!$B$28)/2)^2+COS(RADIANS('Sources & Method'!$B$28))*COS(RADIANS(D24))*SIN(RADIANS(E24-'Sources & Method'!$B$29)/2)^2)) -> 12243.067 | G24: 47 | H24: 42 | I24: =IF(G24=0,0,H24/G24) -> 0.89361702 | J24: 45.563 | K24: 74.604 | L24: 70 | M24: 10 | N24: 3 | O24: 8 | P24: ='Sources & Method'!$B$19 -> 0.3 | Q24: =IF(J24>80,NORMSDIST((Calculator!$B$22-J24)/SQRT((0.3*'Sources & Method'!$B$16)^2+'Sources & Method'!$B$17^2)),(1-P24)*NORMSDIST((Calculator!$B$22-(J24+1))/SQRT((0.3*'Sources & Method'!$B$16)^2+'Sources & Method'!$B$18^2))+P24*NORMSDIST((Calculator!$B$22-85)/SQRT((0.3*'Sources & Method'!$B$16)^2+2.5^2))) -> 0.97401114 | R24: =IF(J24>80,NORMSDIST((Calculator!$B$51-J24)/SQRT((0.3*'Sources & Method'!$B$16)^2+'Sources & Method'!$B$17^2)),(1-P24)*NORMSDIST((Calculator!$B$51-(J24+1))/SQRT((0.3*'Sources & Method'!$B$16)^2+'Sources & Method'!$B$18^2))+P24*NORMSDIST((Calculator!$B$51-85)/SQRT((0.3*'Sources & Method'!$B$16)^2+2.5^2))) -> 0.30845953 | S24: =IF(OR(M24=0,O24="",Calculator!$B$25=0),0,IF(Calculator!$B$25>=999,'Sources & Method'!$B$21,MIN('Sources & Method'!$B$21,NORMSDIST((Calculator!$B$25-O24+0.5)/'Sources & Method'!$B$20)))) -> 0 | T24: =IF(OR(M24=0,O24="",Calculator!$B$54=0),0,IF(Calculator!$B$54>=999,'Sources & Method'!$B$21,MIN('Sources & Method'!$B$21,NORMSDIST((Calculator!$B$54-O24+0.5)/'Sources & Method'!$B$20)))) -> 0.97 | U24: =RANK(J24,$J$2:$J$76) -> 53
A25: N24 | B25: SMPN 24 | C25: D | D25: -6.936421 | E25: 107.58661 | F25: =2*6371000*ASIN(SQRT(SIN(RADIANS(D25-'Sources & Method'!$B$28)/2)^2+COS(RADIANS('Sources & Method'!$B$28))*COS(RADIANS(D25))*SIN(RADIANS(E25-'Sources & Method'!$B$29)/2)^2)) -> 12827.034 | G25: 53 | H25: 57 | I25: =IF(G25=0,0,H25/G25) -> 1.0754717 | J25: 48.499 | K25: 86.229 | L25: 70 | M25: 12 | N25: 8 | O25: 4 | P25: ='Sources & Method'!$B$19 -> 0.3 | Q25: =IF(J25>80,NORMSDIST((Calculator!$B$22-J25)/SQRT((0.3*'Sources & Method'!$B$16)^2+'Sources & Method'!$B$17^2)),(1-P25)*NORMSDIST((Calculator!$B$22-(J25+1))/SQRT((0.3*'Sources & Method'!$B$16)^2+'Sources & Method'!$B$18^2))+P25*NORMSDIST((Calculator!$B$22-85)/SQRT((0.3*'Sources & Method'!$B$16)^2+2.5^2))) -> 0.97401114 | R25: =IF(J25>80,NORMSDIST((Calculator!$B$51-J25)/SQRT((0.3*'Sources & Method'!$B$16)^2+'Sources & Method'!$B$17^2)),(1-P25)*NORMSDIST((Calculator!$B$51-(J25+1))/SQRT((0.3*'Sources & Method'!$B$16)^2+'Sources & Method'!$B$18^2))+P25*NORMSDIST((Calculator!$B$51-85)/SQRT((0.3*'Sources & Method'!$B$16)^2+2.5^2))) -> 0.11955087 | S25: =IF(OR(M25=0,O25="",Calculator!$B$25=0),0,IF(Calculator!$B$25>=999,'Sources & Method'!$B$21,MIN('Sources & Method'!$B$21,NORMSDIST((Calculator!$B$25-O25+0.5)/'Sources & Method'!$B$20)))) -> 0 | T25: =IF(OR(M25=0,O25="",Calculator!$B$54=0),0,IF(Calculator!$B$54>=999,'Sources & Method'!$B$21,MIN('Sources & Method'!$B$21,NORMSDIST((Calculator!$B$54-O25+0.5)/'Sources & Method'!$B$20)))) -> 0.97 | U25: =RANK(J25,$J$2:$J$76) -> 39
A26: N25 | B26: SMPN 25 | C26: D | D26: -6.925586 | E26: 107.60092 | F26: =2*6371000*ASIN(SQRT(SIN(RADIANS(D26-'Sources & Method'!$B$28)/2)^2+COS(RADIANS('Sources & Method'!$B$28))*COS(RADIANS(D26))*SIN(RADIANS(E26-'Sources & Method'!$B$29)/2)^2)) -> 11074.098 | G26: 56 | H26: 74 | I26: =IF(G26=0,0,H26/G26) -> 1.3214286 | J26: 85.543 | K26: 87.891 | L26: 73.34 | M26: 17 | N26: 10 | O26: 1 | P26: ='Sources & Method'!$B$19 -> 0.3 | Q26: =IF(J26>80,NORMSDIST((Calculator!$B$22-J26)/SQRT((0.3*'Sources & Method'!$B$16)^2+'Sources & Method'!$B$17^2)),(1-P26)*NORMSDIST((Calculator!$B$22-(J26+1))/SQRT((0.3*'Sources & Method'!$B$16)^2+'Sources & Method'!$B$18^2))+P26*NORMSDIST((Calculator!$B$22-85)/SQRT((0.3*'Sources & Method'!$B$16)^2+2.5^2))) -> 0.92091057 | R26: =IF(J26>80,NORMSDIST((Calculator!$B$51-J26)/SQRT((0.3*'Sources & Method'!$B$16)^2+'Sources & Method'!$B$17^2)),(1-P26)*NORMSDIST((Calculator!$B$51-(J26+1))/SQRT((0.3*'Sources & Method'!$B$16)^2+'Sources & Method'!$B$18^2))+P26*NORMSDIST((Calculator!$B$51-85)/SQRT((0.3*'Sources & Method'!$B$16)^2+2.5^2))) -> 1.2463523e-46 | S26: =IF(OR(M26=0,O26="",Calculator!$B$25=0),0,IF(Calculator!$B$25>=999,'Sources & Method'!$B$21,MIN('Sources & Method'!$B$21,NORMSDIST((Calculator!$B$25-O26+0.5)/'Sources & Method'!$B$20)))) -> 0 | T26: =IF(OR(M26=0,O26="",Calculator!$B$54=0),0,IF(Calculator!$B$54>=999,'Sources & Method'!$B$21,MIN('Sources & Method'!$B$21,NORMSDIST((Calculator!$B$54-O26+0.5)/'Sources & Method'!$B$20)))) -> 0.97 | U26: =RANK(J26,$J$2:$J$76) -> 28
A27: N26 | B27: SMPN 26 | C27: A | D27: -6.882663 | E27: 107.57746 | F27: =2*6371000*ASIN(SQRT(SIN(RADIANS(D27-'Sources & Method'!$B$28)/2)^2+COS(RADIANS('Sources & Method'!$B$28))*COS(RADIANS(D27))*SIN(RADIANS(E27-'Sources & Method'!$B$29)/2)^2)) -> 14008.953 | G27: 55 | H27: 52 | I27: =IF(G27=0,0,H27/G27) -> 0.94545455 | J27: 48.569 | K27: 85.98 | L27: 75 | M27: 10 | N27: 8 | O27: 10 | P27: ='Sources & Method'!$B$19 -> 0.3 | Q27: =IF(J27>80,NORMSDIST((Calculator!$B$22-J27)/SQRT((0.3*'Sources & Method'!$B$16)^2+'Sources & Method'!$B$17^2)),(1-P27)*NORMSDIST((Calculator!$B$22-(J27+1))/SQRT((0.3*'Sources & Method'!$B$16)^2+'Sources & Method'!$B$18^2))+P27*NORMSDIST((Calculator!$B$22-85)/SQRT((0.3*'Sources & Method'!$B$16)^2+2.5^2))) -> 0.97401114 | R27: =IF(J27>80,NORMSDIST((Calculator!$B$51-J27)/SQRT((0.3*'Sources & Method'!$B$16)^2+'Sources & Method'!$B$17^2)),(1-P27)*NORMSDIST((Calculator!$B$51-(J27+1))/SQRT((0.3*'Sources & Method'!$B$16)^2+'Sources & Method'!$B$18^2))+P27*NORMSDIST((Calculator!$B$51-85)/SQRT((0.3*'Sources & Method'!$B$16)^2+2.5^2))) -> 0.11618567 | S27: =IF(OR(M27=0,O27="",Calculator!$B$25=0),0,IF(Calculator!$B$25>=999,'Sources & Method'!$B$21,MIN('Sources & Method'!$B$21,NORMSDIST((Calculator!$B$25-O27+0.5)/'Sources & Method'!$B$20)))) -> 0 | T27: =IF(OR(M27=0,O27="",Calculator!$B$54=0),0,IF(Calculator!$B$54>=999,'Sources & Method'!$B$21,MIN('Sources & Method'!$B$21,NORMSDIST((Calculator!$B$54-O27+0.5)/'Sources & Method'!$B$20)))) -> 0.97 | U27: =RANK(J27,$J$2:$J$76) -> 38
A28: N27 | B28: SMPN 27 | C28: A | D28: -6.905408 | E28: 107.63477 | F28: =2*6371000*ASIN(SQRT(SIN(RADIANS(D28-'Sources & Method'!$B$28)/2)^2+COS(RADIANS('Sources & Method'!$B$28))*COS(RADIANS(D28))*SIN(RADIANS(E28-'Sources & Method'!$B$29)/2)^2)) -> 7311.8885 | G28: 34 | H28: 31 | I28: =IF(G28=0,0,H28/G28) -> 0.91176471 | J28: 85.718 | K28: 88.086 | L28: 73.33 | M28: 23 | N28: 18 | O28: 11 | P28: ='Sources & Method'!$B$19 -> 0.3 | Q28: =IF(J28>80,NORMSDIST((Calculator!$B$22-J28)/SQRT((0.3*'Sources & Method'!$B$16)^2+'Sources & Method'!$B$17^2)),(1-P28)*NORMSDIST((Calculator!$B$22-(J28+1))/SQRT((0.3*'Sources & Method'!$B$16)^2+'Sources & Method'!$B$18^2))+P28*NORMSDIST((Calculator!$B$22-85)/SQRT((0.3*'Sources & Method'!$B$16)^2+2.5^2))) -> 0.91116303 | R28: =IF(J28>80,NORMSDIST((Calculator!$B$51-J28)/SQRT((0.3*'Sources & Method'!$B$16)^2+'Sources & Method'!$B$17^2)),(1-P28)*NORMSDIST((Calculator!$B$51-(J28+1))/SQRT((0.3*'Sources & Method'!$B$16)^2+'Sources & Method'!$B$18^2))+P28*NORMSDIST((Calculator!$B$51-85)/SQRT((0.3*'Sources & Method'!$B$16)^2+2.5^2))) -> 5.0139417e-47 | S28: =IF(OR(M28=0,O28="",Calculator!$B$25=0),0,IF(Calculator!$B$25>=999,'Sources & Method'!$B$21,MIN('Sources & Method'!$B$21,NORMSDIST((Calculator!$B$25-O28+0.5)/'Sources & Method'!$B$20)))) -> 0 | T28: =IF(OR(M28=0,O28="",Calculator!$B$54=0),0,IF(Calculator!$B$54>=999,'Sources & Method'!$B$21,MIN('Sources & Method'!$B$21,NORMSDIST((Calculator!$B$54-O28+0.5)/'Sources & Method'!$B$20)))) -> 0.97 | U28: =RANK(J28,$J$2:$J$76) -> 25
A29: N28 | B29: SMPN 28 | C29: C | D29: -6.937755 | E29: 107.62611 | F29: =2*6371000*ASIN(SQRT(SIN(RADIANS(D29-'Sources & Method'!$B$28)/2)^2+COS(RADIANS('Sources & Method'!$B$28))*COS(RADIANS(D29))*SIN(RADIANS(E29-'Sources & Method'!$B$29)/2)^2)) -> 8642.5927 | G29: 39 | H29: 52 | I29: =IF(G29=0,0,H29/G29) -> 1.3333333 | J29: 89.649 | K29: 90.875 | L29: 80 | M29: 26 | N29: 38 | O29: 14 | P29: ='Sources & Method'!$B$19 -> 0.3 | Q29: =IF(J29>80,NORMSDIST((Calculator!$B$22-J29)/SQRT((0.3*'Sources & Method'!$B$16)^2+'Sources & Method'!$B$17^2)),(1-P29)*NORMSDIST((Calculator!$B$22-(J29+1))/SQRT((0.3*'Sources & Method'!$B$16)^2+'Sources & Method'!$B$18^2))+P29*NORMSDIST((Calculator!$B$22-85)/SQRT((0.3*'Sources & Method'!$B$16)^2+2.5^2))) -> 0.47078194 | R29: =IF(J29>80,NORMSDIST((Calculator!$B$51-J29)/SQRT((0.3*'Sources & Method'!$B$16)^2+'Sources & Method'!$B$17^2)),(1-P29)*NORMSDIST((Calculator!$B$51-(J29+1))/SQRT((0.3*'Sources & Method'!$B$16)^2+'Sources & Method'!$B$18^2))+P29*NORMSDIST((Calculator!$B$51-85)/SQRT((0.3*'Sources & Method'!$B$16)^2+2.5^2))) -> 2.2954238e-56 | S29: =IF(OR(M29=0,O29="",Calculator!$B$25=0),0,IF(Calculator!$B$25>=999,'Sources & Method'!$B$21,MIN('Sources & Method'!$B$21,NORMSDIST((Calculator!$B$25-O29+0.5)/'Sources & Method'!$B$20)))) -> 0 | T29: =IF(OR(M29=0,O29="",Calculator!$B$54=0),0,IF(Calculator!$B$54>=999,'Sources & Method'!$B$21,MIN('Sources & Method'!$B$21,NORMSDIST((Calculator!$B$54-O29+0.5)/'Sources & Method'!$B$20)))) -> 0.97 | U29: =RANK(J29,$J$2:$J$76) -> 11
A30: N29 | B30: SMPN 29 | C30: A | D30: -6.860534 | E30: 107.58603 | F30: =2*6371000*ASIN(SQRT(SIN(RADIANS(D30-'Sources & Method'!$B$28)/2)^2+COS(RADIANS('Sources & Method'!$B$28))*COS(RADIANS(D30))*SIN(RADIANS(E30-'Sources & Method'!$B$29)/2)^2)) -> 13941.218 | G30: 49 | H30: 24 | I30: =IF(G30=0,0,H30/G30) -> 0.48979592 | J30: 45.667 | K30: 81.506 | L30: 70 | M30: 16 | N30: 16 | O30: 10 | P30: ='Sources & Method'!$B$19 -> 0.3 | Q30: =IF(J30>80,NORMSDIST((Calculator!$B$22-J30)/SQRT((0.3*'Sources & Method'!$B$16)^2+'Sources & Method'!$B$17^2)),(1-P30)*NORMSDIST((Calculator!$B$22-(J30+1))/SQRT((0.3*'Sources & Method'!$B$16)^2+'Sources & Method'!$B$18^2))+P30*NORMSDIST((Calculator!$B$22-85)/SQRT((0.3*'Sources & Method'!$B$16)^2+2.5^2))) -> 0.97401114 | R30: =IF(J30>80,NORMSDIST((Calculator!$B$51-J30)/SQRT((0.3*'Sources & Method'!$B$16)^2+'Sources & Method'!$B$17^2)),(1-P30)*NORMSDIST((Calculator!$B$51-(J30+1))/SQRT((0.3*'Sources & Method'!$B$16)^2+'Sources & Method'!$B$18^2))+P30*NORMSDIST((Calculator!$B$51-85)/SQRT((0.3*'Sources & Method'!$B$16)^2+2.5^2))) -> 0.30063411 | S30: =IF(OR(M30=0,O30="",Calculator!$B$25=0),0,IF(Calculator!$B$25>=999,'Sources & Method'!$B$21,MIN('Sources & Method'!$B$21,NORMSDIST((Calculator!$B$25-O30+0.5)/'Sources & Method'!$B$20)))) -> 0 | T30: =IF(OR(M30=0,O30="",Calculator!$B$54=0),0,IF(Calculator!$B$54>=999,'Sources & Method'!$B$21,MIN('Sources & Method'!$B$21,NORMSDIST((Calculator!$B$54-O30+0.5)/'Sources & Method'!$B$20)))) -> 0.97 | U30: =RANK(J30,$J$2:$J$76) -> 51
A31: N30 | B31: SMPN 30 | C31: C | D31: -6.940616 | E31: 107.64478 | F31: =2*6371000*ASIN(SQRT(SIN(RADIANS(D31-'Sources & Method'!$B$28)/2)^2+COS(RADIANS('Sources & Method'!$B$28))*COS(RADIANS(D31))*SIN(RADIANS(E31-'Sources & Method'!$B$29)/2)^2)) -> 6849.5587 | G31: 34 | H31: 61 | I31: =IF(G31=0,0,H31/G31) -> 1.7941176 | J31: 89.194 | K31: 90.581 | L31: 78.34 | M31: 23 | N31: 26 | O31: 10 | P31: ='Sources & Method'!$B$19 -> 0.3 | Q31: =IF(J31>80,NORMSDIST((Calculator!$B$22-J31)/SQRT((0.3*'Sources & Method'!$B$16)^2+'Sources & Method'!$B$17^2)),(1-P31)*NORMSDIST((Calculator!$B$22-(J31+1))/SQRT((0.3*'Sources & Method'!$B$16)^2+'Sources & Method'!$B$18^2))+P31*NORMSDIST((Calculator!$B$22-85)/SQRT((0.3*'Sources & Method'!$B$16)^2+2.5^2))) -> 0.53633363 | R31: =IF(J31>80,NORMSDIST((Calculator!$B$51-J31)/SQRT((0.3*'Sources & Method'!$B$16)^2+'Sources & Method'!$B$17^2)),(1-P31)*NORMSDIST((Calculator!$B$51-(J31+1))/SQRT((0.3*'Sources & Method'!$B$16)^2+'Sources & Method'!$B$18^2))+P31*NORMSDIST((Calculator!$B$51-85)/SQRT((0.3*'Sources & Method'!$B$16)^2+2.5^2))) -> 3.0659304e-55 | S31: =IF(OR(M31=0,O31="",Calculator!$B$25=0),0,IF(Calculator!$B$25>=999,'Sources & Method'!$B$21,MIN('Sources & Method'!$B$21,NORMSDIST((Calculator!$B$25-O31+0.5)/'Sources & Method'!$B$20)))) -> 0 | T31: =IF(OR(M31=0,O31="",Calculator!$B$54=0),0,IF(Calculator!$B$54>=999,'Sources & Method'!$B$21,MIN('Sources & Method'!$B$21,NORMSDIST((Calculator!$B$54-O31+0.5)/'Sources & Method'!$B$20)))) -> 0.97 | U31: =RANK(J31,$J$2:$J$76) -> 13
... A42: N41 | B42: SMPN 41 | C42: D | D42: -6.915342 | E42: 107.59009 | F42: =2*6371000*ASIN(SQRT(SIN(RADIANS(D42-'Sources & Method'!$B$28)/2)^2+COS(RADIANS('Sources & Method'!$B$28))*COS(RADIANS(D42))*SIN(RADIANS(E42-'Sources & Method'!$B$29)/2)^2)) -> 12189.463 | G42: 62 | H42: 56 | I42: =IF(G42=0,0,H42/G42) -> 0.90322581 | J42: 47.117 | K42: 86.073 | L42: 70 | M42: 18 | N42: 15 | O42: 4 | P42: ='Sources & Method'!$B$19 -> 0.3 | Q42: =IF(J42>80,NORMSDIST((Calculator!$B$22-J42)/SQRT((0.3*'Sources & Method'!$B$16)^2+'Sources & Method'!$B$17^2)),(1-P42)*NORMSDIST((Calculator!$B$22-(J42+1))/SQRT((0.3*'Sources & Method'!$B$16)^2+'Sources & Method'!$B$18^2))+P42*NORMSDIST((Calculator!$B$22-85)/SQRT((0.3*'Sources & Method'!$B$16)^2+2.5^2))) -> 0.97401114 | R42: =IF(J42>80,NORMSDIST((Calculator!$B$51-J42)/SQRT((0.3*'Sources & Method'!$B$16)^2+'Sources & Method'!$B$17^2)),(1-P42)*NORMSDIST((Calculator!$B$51-(J42+1))/SQRT((0.3*'Sources & Method'!$B$16)^2+'Sources & Method'!$B$18^2))+P42*NORMSDIST((Calculator!$B$51-85)/SQRT((0.3*'Sources & Method'!$B$16)^2+2.5^2))) -> 0.19816757 | S42: =IF(OR(M42=0,O42="",Calculator!$B$25=0),0,IF(Calculator!$B$25>=999,'Sources & Method'!$B$21,MIN('Sources & Method'!$B$21,NORMSDIST((Calculator!$B$25-O42+0.5)/'Sources & Method'!$B$20)))) -> 0 | T42: =IF(OR(M42=0,O42="",Calculator!$B$54=0),0,IF(Calculator!$B$54>=999,'Sources & Method'!$B$21,MIN('Sources & Method'!$B$21,NORMSDIST((Calculator!$B$54-O42+0.5)/'Sources & Method'!$B$20)))) -> 0.97 | U42: =RANK(J42,$J$2:$J$76) -> 44
A43: N42 | B43: SMPN 42 | C43: B | D43: -6.9575 | E43: 107.6721 | F43: =2*6371000*ASIN(SQRT(SIN(RADIANS(D43-'Sources & Method'!$B$28)/2)^2+COS(RADIANS('Sources & Method'!$B$28))*COS(RADIANS(D43))*SIN(RADIANS(E43-'Sources & Method'!$B$29)/2)^2)) -> 5810.7191 | G43: 69 | H43: 20 | I43: =IF(G43=0,0,H43/G43) -> 0.28985507 | J43: 43.032 | K43: 46.394 | L43: 70 | M43: 4 | N43: 0 | O43: 4 | P43: =MIN(0.6,COUNTIF(INDEX('Report 2023-2025'!$B$2:$D$20,MATCH(A43,'Report 2023-2025'!$A$2:$A$20,0),0),">80")/4*0.6) -> 0 | Q43: =IF(J43>80,NORMSDIST((Calculator!$B$22-J43)/SQRT((0.3*'Sources & Method'!$B$16)^2+'Sources & Method'!$B$17^2)),(1-P43)*NORMSDIST((Calculator!$B$22-(J43+1))/SQRT((0.3*'Sources & Method'!$B$16)^2+'Sources & Method'!$B$18^2))+P43*NORMSDIST((Calculator!$B$22-85)/SQRT((0.3*'Sources & Method'!$B$16)^2+2.5^2))) -> 1 | R43: =IF(J43>80,NORMSDIST((Calculator!$B$51-J43)/SQRT((0.3*'Sources & Method'!$B$16)^2+'Sources & Method'!$B$17^2)),(1-P43)*NORMSDIST((Calculator!$B$51-(J43+1))/SQRT((0.3*'Sources & Method'!$B$16)^2+'Sources & Method'!$B$18^2))+P43*NORMSDIST((Calculator!$B$51-85)/SQRT((0.3*'Sources & Method'!$B$16)^2+2.5^2))) -> 0.70604033 | S43: =IF(OR(M43=0,O43="",Calculator!$B$25=0),0,IF(Calculator!$B$25>=999,'Sources & Method'!$B$21,MIN('Sources & Method'!$B$21,NORMSDIST((Calculator!$B$25-O43+0.5)/'Sources & Method'!$B$20)))) -> 0 | T43: =IF(OR(M43=0,O43="",Calculator!$B$54=0),0,IF(Calculator!$B$54>=999,'Sources & Method'!$B$21,MIN('Sources & Method'!$B$21,NORMSDIST((Calculator!$B$54-O43+0.5)/'Sources & Method'!$B$20)))) -> 0.97 | U43: =RANK(J43,$J$2:$J$76) -> 65
A44: N43 | B44: SMPN 43 | C44: C | D44: -6.925611 | E44: 107.60675 | F44: =2*6371000*ASIN(SQRT(SIN(RADIANS(D44-'Sources & Method'!$B$28)/2)^2+COS(RADIANS('Sources & Method'!$B$28))*COS(RADIANS(D44))*SIN(RADIANS(E44-'Sources & Method'!$B$29)/2)^2)) -> 10436.069 | G44: 44 | H44: 46 | I44: =IF(G44=0,0,H44/G44) -> 1.0454545 | J44: 85.682 | K44: 87.652 | L44: 71.67 | M44: 29 | N44: 27 | O44: 8 | P44: ='Sources & Method'!$B$19 -> 0.3 | Q44: =IF(J44>80,NORMSDIST((Calculator!$B$22-J44)/SQRT((0.3*'Sources & Method'!$B$16)^2+'Sources & Method'!$B$17^2)),(1-P44)*NORMSDIST((Calculator!$B$22-(J44+1))/SQRT((0.3*'Sources & Method'!$B$16)^2+'Sources & Method'!$B$18^2))+P44*NORMSDIST((Calculator!$B$22-85)/SQRT((0.3*'Sources & Method'!$B$16)^2+2.5^2))) -> 0.91323801 | R44: =IF(J44>80,NORMSDIST((Calculator!$B$51-J44)/SQRT((0.3*'Sources & Method'!$B$16)^2+'Sources & Method'!$B$17^2)),(1-P44)*NORMSDIST((Calculator!$B$51-(J44+1))/SQRT((0.3*'Sources & Method'!$B$16)^2+'Sources & Method'!$B$18^2))+P44*NORMSDIST((Calculator!$B$51-85)/SQRT((0.3*'Sources & Method'!$B$16)^2+2.5^2))) -> 6.0488489e-47 | S44: =IF(OR(M44=0,O44="",Calculator!$B$25=0),0,IF(Calculator!$B$25>=999,'Sources & Method'!$B$21,MIN('Sources & Method'!$B$21,NORMSDIST((Calculator!$B$25-O44+0.5)/'Sources & Method'!$B$20)))) -> 0 | T44: =IF(OR(M44=0,O44="",Calculator!$B$54=0),0,IF(Calculator!$B$54>=999,'Sources & Method'!$B$21,MIN('Sources & Method'!$B$21,NORMSDIST((Calculator!$B$54-O44+0.5)/'Sources & Method'!$B$20)))) -> 0.97 | U44: =RANK(J44,$J$2:$J$76) -> 26
